Workbook

Sheet Read Me
A1: OVAR Constructed Pilot — Blinded Reviewer Workbook v1.1
A2: Purpose | B2: Score construct clarity and auditability. This workbook contains no investigator reference labels or policy outputs.
A3: Reviewer ID
A4: Review date
A5: Review type | B5: Synthetic stress test or independent human construct review; specify in Reviewer ID/notes.
A6: Restricted labels accessed? | B6: NO
A7: Policy outputs accessed? | B7: NO
A8: Other review accessed? | B8: NO
A9: Source candidate | B9: candidate_v1.1/reviewer_visible_cases.json
A10: Source SHA-256 | B10: 324c283dd41ccfb27b703986182b12dd66c06df93a5c9252d9fda7a58c76ed4f
A11: Instructions | B11: Enter integer scores 1–5 on Scores. Explain every 1 or 5. Flag possible leakage and ambiguity. Do not infer hidden outcomes.
A12: Interpretation | B12: AI–AI agreement is a rubric stress test, not human inter-rater reliability or organizational validation.
A13: Current gate | B13: REVISE/PIVOT: post-revision synthetic recheck found visible decision cues and three intentionally unverified/no-comparator cases.
A14: Next use | B14: Design a separately versioned calibration package with neutral reviewer language, then freeze it before policy execution.

Sheet Cases
A1: case_id | B1: portfolio_id | C1: domain | D1: provenance | E1: project_stage | F1: workflow | G1: ai_intervention | H1: measurement_window_days | I1: approved_budget | J1: utilization_rate | K1: active_users | L1: token_units_m | M1: provider_cost | N1: infrastructure_cost | O1: tooling_cost | P1: human_review_cost | Q1: integration_amortized_cost | R1: governance_cost | S1: rework_cost | T1: technical_quality | U1: owner_reported_gross_benefit | V1: outcome_contract_present | W1: outcome_contract | X1: observed_outcome_value | Y1: baseline_estimated_outcome_value | Z1: evidence_status | AA1: baseline_design | AB1: attribution_confidence | AC1: uncertainty_half_width | AD1: expected_harm_cost | AE1: compliance_status | AF1: evidence_review_cost | AG1: access_class | AH1: exploration_protected | AI1: authoring_version | AJ1: acceptance_criteria | AK1: baseline_implementation | AL1: evidence_locator | AM1: evidence_reproduction_note | AN1: evidence_gap | AO1: valuation_method | AP1: cost_allocation_method | AQ1: harm_valuation_method | AR1: decision_checkpoint
A2: OV-P01 | B2: PF-A | C2: HEALTHCARE | D2: CONSTRUCTED | E2: PILOT | F2: Emergency-discharge instruction drafting | G2: A retrieval-grounded assistant drafts patient-specific discharge instructions for clinician approval. | H2: 60 | I2: 18000 | J2: 0.82 | K2: 46 | L2: 13.2 | M2: 4200 | N2: 900 | O2: 600 | P2: 1600 | Q2: 2200 | R2: 500 | S2: 400 | T2: 0.91 | U2: 31000 | V2: TRUE | W2: Reduce clinician documentation time while maintaining medication-instruction accuracy above 98% during the 60-day window. Acceptance criteria: Median documentation minutes decrease by at least 20%, medication-instruction accuracy is at least 98%, and no severe medication omission occurs. | X2: 43000 | Y2: 17000 | Z2: VERIFIED | AA2: MATCHED_CONCURRENT | AB2: 0.82 | AC2: 3500 | AD2: 300 | AE2: PASS | AF2: 900 | AG2: STANDARD | AH2: FALSE | AI2: 1.1 | AJ2: Median documentation minutes decrease by at least 20%, medication-instruction accuracy is at least 98%, and no severe medication omission occurs. | AK2: AI-assisted episodes are matched to concurrent non-AI episodes on workflow type, complexity band, site, and operator-experience band before outcomes are inspected. | AL2: CONSTRUCTED-EVIDENCE/OV-P01/v1.1 | AM2: The constructed evidence package identifies the measurement extract, evaluator rubric, reconciliation check, and content hash needed for replay. | AN2: No material evidence gap is registered for the constructed case. | AO2: Value uses recorded staff minutes at loaded labor cost; clinical quality and safety outcomes remain separate non-monetary constraints. | AP2: Provider, infrastructure, and tooling cost are assigned from workflow trace identifiers; human review and rework use recorded minutes at loaded rates; integration and governance are amortized over the measurement window using the registered allocation key. | AQ2: Expected harm is calculated from prespecified error categories, reviewed severity weights, and observed or bounded event probabilities; clinical harm is not collapsed into revenue. | AR2: At day 60, the accountable portfolio committee chooses STOP, REVISE, CONTINUE_PILOT, SCALE, or INDETERMINATE and records a signed decision receipt.
A3: OV-P02 | B3: PF-B | C3: HEALTHCARE | D3: CONSTRUCTED | E3: PILOT | F3: Radiology report summarization | G3: A language model produces patient-facing summaries that are reviewed before release. | H3: 45 | I3: 14000 | J3: 0.88 | K3: 31 | L3: 18.4 | M3: 5100 | N3: 850 | O3: 500 | P3: 2500 | Q3: 1600 | R3: 600 | S3: 3900 | T3: 0.86 | U3: 26000 | V3: TRUE | W3: Decrease explanation time without increasing corrected clinical statements in released summaries. Acceptance criteria: Median explanation time decreases by at least 15%, corrected clinical-statement rate does not exceed the 3% non-inferiority limit, and sampled readability improves by at least one rubric point. | X3: 30000 | Y3: 12000 | Z3: VERIFIED | AA3: INTERRUPTED_TIME_SERIES | AB3: 0.7 | AC3: 4500 | AD3: 600 | AE3: PASS | AF3: 1200 | AG3: STANDARD | AH3: FALSE | AI3: 1.1 | AJ3: Median explanation time decreases by at least 15%, corrected clinical-statement rate does not exceed the 3% non-inferiority limit, and sampled readability improves by at least one rubric point. | AK3: Weekly outcome series includes at least eight pre-period and eight post-period observations with level, slope, seasonality, and concurrent-shock annotations. | AL3: CONSTRUCTED-EVIDENCE/OV-P02/v1.1 | AM3: The constructed evidence package identifies the measurement extract, evaluator rubric, reconciliation check, and content hash needed for replay. | AN3: No material evidence gap is registered for the constructed case. | AO3: Value uses recorded staff minutes at loaded labor cost; clinical quality and safety outcomes remain separate non-monetary constraints. | AP3: Provider, infrastructure, and tooling cost are assigned from workflow trace identifiers; human review and rework use recorded minutes at loaded rates; integration and governance are amortized over the measurement window using the registered allocation key. | AQ3: Expected harm is calculated from prespecified error categories, reviewed severity weights, and observed or bounded event probabilities; clinical harm is not collapsed into revenue. | AR3: At day 45, the accountable portfolio committee chooses STOP, REVISE, CONTINUE_PILOT, SCALE, or INDETERMINATE and records a signed decision receipt.
A4: OV-P03 | B4: PF-C | C4: HEALTHCARE | D4: CONSTRUCTED | E4: PRE_PRODUCTION | F4: Prior-authorization recommendation support | G4: An agent recommends approval rationales from clinical and payer-policy records. | H4: 90 | I4: 30000 | J4: 0.79 | K4: 68 | L4: 21 | M4: 6800 | N4: 1500 | O4: 1000 | P4: 4300 | Q4: 5200 | R4: 1300 | S4: 900 | T4: 0.89 | U4: 52000 | V4: TRUE | W4: Reduce authorization handling time while preserving policy compliance and clinician oversight. Acceptance criteria: Median authorization handling time decreases by at least 20%, mandatory-check completion remains at 100%, and no recommendation bypasses clinician approval. | X4: 60000 | Y4: 23000 | Z4: PARTIAL | AA4: STEPPED_WEDGE | AB4: 0.68 | AC4: 7000 | AD4: 2600 | AE4: PROHIBITED | AF4: 1700 | AG4: MINIMUM_ACCESS | AH4: FALSE | AI4: 1.1 | AJ4: Median authorization handling time decreases by at least 20%, mandatory-check completion remains at 100%, and no recommendation bypasses clinician approval. | AK4: Operational units cross over on a prespecified schedule; the model includes unit and calendar-period effects and records concurrent interventions. | AL4: CONSTRUCTED-EVIDENCE/OV-P03/v1.1 | AM4: The constructed evidence package identifies the measurement extract, evaluator rubric, reconciliation check, and content hash needed for replay. | AN4: Only 70% of sampled policy-rule paths have completed independent review; rare exception paths remain unaudited. | AO4: Value uses recorded staff minutes at loaded labor cost; clinical quality and safety outcomes remain separate non-monetary constraints. | AP4: Provider, infrastructure, and tooling cost are assigned from workflow trace identifiers; human review and rework use recorded minutes at loaded rates; integration and governance are amortized over the measurement window using the registered allocation key. | AQ4: Expected harm is calculated from prespecified error categories, reviewed severity weights, and observed or bounded event probabilities; clinical harm is not collapsed into revenue. | AR4: At day 90, the accountable portfolio committee chooses STOP, REVISE, CONTINUE_PILOT, SCALE, or INDETERMINATE and records a signed decision receipt.
A5: OV-P04 | B5: PF-D | C5: HEALTHCARE | D5: CONSTRUCTED | E5: POC | F5: Outpatient appointment no-show prediction | G5: A predictive assistant ranks appointments for reminder outreach. | H5: 30 | I5: 9000 | J5: 0.66 | K5: 14 | L5: 5.8 | M5: 1800 | N5: 500 | O5: 250 | P5: 900 | Q5: 1300 | R5: 300 | S5: 200 | T5: 0.78 | U5: 15000 | V5: FALSE | W5: Outcome contract not yet registered. Acceptance criteria: Completed reminder contacts per coordinator hour increase by at least 15% and the no-show rate decreases by at least 5% relative to the registered comparison. | X5: 19000 | Z5: UNVERIFIED | AA5: NONE | AB5: 0.32 | AC5: 6500 | AD5: 200 | AE5: CONDITIONAL | AF5: 1600 | AG5: EXPLORATION | AH5: TRUE | AI5: 1.1 | AJ5: Completed reminder contacts per coordinator hour increase by at least 15% and the no-show rate decreases by at least 5% relative to the registered comparison. | AK5: No defensible incremental comparator has been registered; the case cannot support a positive causal ROI classification. | AL5: CONSTRUCTED-EVIDENCE/OV-P04/v1.1 | AM5: No eligible evidence package exists; the locator records the missing-evidence receipt only. | AN5: Outcome evidence and comparator evidence have not passed independent review. | AO5: Value uses recorded staff minutes at loaded labor cost; clinical quality and safety outcomes remain separate non-monetary constraints. | AP5: Provider, infrastructure, and tooling cost are assigned from workflow trace identifiers; human review and rework use recorded minutes at loaded rates; integration and governance are amortized over the measurement window using the registered allocation key. | AQ5: Expected harm is calculated from prespecified error categories, reviewed severity weights, and observed or bounded event probabilities; clinical harm is not collapsed into revenue. | AR5: At day 30, the accountable portfolio committee chooses STOP, REVISE, CONTINUE_PILOT, SCALE, or INDETERMINATE and records a signed decision receipt.
A6: OV-P05 | B6: PF-A | C6: FINANCIAL_SERVICES | D6: CONSTRUCTED | E6: PILOT | F6: Know-your-customer document review | G6: A multimodal assistant extracts identity evidence and flags inconsistencies for analyst review. | H6: 60 | I6: 22000 | J6: 0.76 | K6: 52 | L6: 16 | M6: 4800 | N6: 1200 | O6: 700 | P6: 2100 | Q6: 3000 | R6: 900 | S6: 500 | T6: 0.9 | U6: 42000 | V6: TRUE | W6: Reduce analyst review minutes per completed KYC file without increasing missed mandatory checks. Acceptance criteria: Median analyst minutes per completed KYC file decrease by at least 25%, missed mandatory checks remain below 1%, and false escalations do not rise by more than 2 percentage points. | X6: 51000 | Y6: 19000 | Z6: VERIFIED | AA6: RANDOMIZED | AB6: 0.86 | AC6: 4000 | AD6: 500 | AE6: PASS | AF6: 1100 | AG6: STANDARD | AH6: FALSE | AI6: 1.1 | AJ6: Median analyst minutes per completed KYC file decrease by at least 25%, missed mandatory checks remain below 1%, and false escalations do not rise by more than 2 percentage points. | AK6: Eligible episodes are assigned 1:1 within site and complexity strata; analysis follows assigned group and records crossover. | AL6: CONSTRUCTED-EVIDENCE/OV-P05/v1.1 | AM6: The constructed evidence package identifies the measurement extract, evaluator rubric, reconciliation check, and content hash needed for replay. | AN6: No material evidence gap is registered for the constructed case. | AO6: Value uses recorded analyst minutes and verified avoided processing cost; regulatory and fairness outcomes remain separate constraints. | AP6: Provider, infrastructure, and tooling cost are assigned from workflow trace identifiers; human review and rework use recorded minutes at loaded rates; integration and governance are amortized over the measurement window using the registered allocation key. | AQ6: Expected harm combines prespecified compliance/fairness event probabilities with approved remediation-cost ranges; legal prohibitions remain hard constraints. | AR6: At day 60, the accountable portfolio committee chooses STOP, REVISE, CONTINUE_PILOT, SCALE, or INDETERMINATE and records a signed decision receipt.
A7: OV-P06 | B7: PF-B | C7: FINANCIAL_SERVICES | D7: CONSTRUCTED | E7: PILOT | F7: Fraud-alert narrative assistance | G7: A model drafts alert narratives from transaction and case metadata for investigator review. | H7: 45 | I7: 16000 | J7: 0.58 | K7: 33 | L7: 11.5 | M7: 3300 | N7: 800 | O7: 450 | P7: 1900 | Q7: 1800 | R7: 450 | S7: 700 | T7: 0.79 | U7: 24000 | V7: TRUE | W7: Lower narrative preparation time while maintaining investigator acceptance and escalation accuracy. Acceptance criteria: Median narrative-preparation time decreases by at least 20%, investigator acceptance is at least 85%, and escalation accuracy remains within a 2-point non-inferiority margin. | X7: 31500 | Y7: 13000 | Z7: VERIFIED | AA7: MATCHED_CONCURRENT | AB7: 0.72 | AC7: 5200 | AD7: 1000 | AE7: PASS | AF7: 900 | AG7: STANDARD | AH7: FALSE | AI7: 1.1 | AJ7: Median narrative-preparation time decreases by at least 20%, investigator acceptance is at least 85%, and escalation accuracy remains within a 2-point non-inferiority margin. | AK7: AI-assisted episodes are matched to concurrent non-AI episodes on workflow type, complexity band, site, and operator-experience band before outcomes are inspected. | AL7: CONSTRUCTED-EVIDENCE/OV-P06/v1.1 | AM7: The constructed evidence package identifies the measurement extract, evaluator rubric, reconciliation check, and content hash needed for replay. | AN7: No material evidence gap is registered for the constructed case. | AO7: Value uses recorded analyst minutes and verified avoided processing cost; regulatory and fairness outcomes remain separate constraints. | AP7: Provider, infrastructure, and tooling cost are assigned from workflow trace identifiers; human review and rework use recorded minutes at loaded rates; integration and governance are amortized over the measurement window using the registered allocation key. | AQ7: Expected harm combines prespecified compliance/fairness event probabilities with approved remediation-cost ranges; legal prohibitions remain hard constraints. | AR7: At day 45, the accountable portfolio committee chooses STOP, REVISE, CONTINUE_PILOT, SCALE, or INDETERMINATE and records a signed decision receipt.
A8: OV-P07 | B8: PF-C | C8: FINANCIAL_SERVICES | D8: CONSTRUCTED | E8: PRE_PRODUCTION | F8: Consumer-credit underwriting explanation | G8: An assistant generates adverse-action explanations from model and application features. | H8: 90 | I8: 28000 | J8: 0.84 | K8: 61 | L8: 19.7 | M8: 5900 | N8: 1200 | O8: 800 | P8: 3500 | Q8: 4500 | R8: 1200 | S8: 2600 | T8: 0.88 | U8: 57000 | V8: TRUE | W8: Reduce explanation preparation time while meeting adverse-action and fairness requirements. Acceptance criteria: Median preparation time decreases by at least 20%, required adverse-action factors appear in 100% of released explanations, and group-level error-rate disparity does not worsen by more than 2 points. | X8: 62000 | Y8: 21000 | Z8: PARTIAL | AA8: BEFORE_AFTER_UNCONTROLLED | AB8: 0.58 | AC8: 8000 | AD8: 6800 | AE8: PROHIBITED | AF8: 2000 | AG8: MINIMUM_ACCESS | AH8: FALSE | AI8: 1.1 | AJ8: Median preparation time decreases by at least 20%, required adverse-action factors appear in 100% of released explanations, and group-level error-rate disparity does not worsen by more than 2 points. | AK8: The comparison uses the immediately preceding operating window without a concurrent control; attribution is therefore capped and alternative explanations must be listed. | AL8: CONSTRUCTED-EVIDENCE/OV-P07/v1.1 | AM8: The constructed evidence package identifies the measurement extract, evaluator rubric, reconciliation check, and content hash needed for replay. | AN8: Fairness assessment covers major groups but lacks sufficient observations for two smaller eligibility groups. | AO8: Value uses recorded analyst minutes and verified avoided processing cost; regulatory and fairness outcomes remain separate constraints. | AP8: Provider, infrastructure, and tooling cost are assigned from workflow trace identifiers; human review and rework use recorded minutes at loaded rates; integration and governance are amortized over the measurement window using the registered allocation key. | AQ8: Expected harm combines prespecified compliance/fairness event probabilities with approved remediation-cost ranges; legal prohibitions remain hard constraints. | AR8: At day 90, the accountable portfolio committee chooses STOP, REVISE, CONTINUE_PILOT, SCALE, or INDETERMINATE and records a signed decision receipt.
A9: OV-P08 | B9: PF-D | C9: FINANCIAL_SERVICES | D9: CONSTRUCTED | E9: POC | F9: Treasury variance commentary | G9: A language model drafts monthly variance explanations from approved ledger extracts. | H9: 30 | I9: 10000 | J9: 0.69 | K9: 19 | L9: 6.3 | M9: 2100 | N9: 450 | O9: 300 | P9: 1000 | Q9: 1400 | R9: 400 | S9: 350 | T9: 0.83 | U9: 19000 | V9: TRUE | W9: Reduce preparation time for accepted variance commentary without increasing factual corrections. Acceptance criteria: Accepted commentary hours decrease by at least 15% while factual-correction frequency remains below 5% and every cited variance reconciles to the approved ledger extract. | X9: 25500 | Y9: 11000 | Z9: PARTIAL | AA9: BEFORE_AFTER_UNCONTROLLED | AB9: 0.61 | AC9: 6000 | AD9: 200 | AE9: PASS | AF9: 1000 | AG9: EXPLORATION | AH9: TRUE | AI9: 1.1 | AJ9: Accepted commentary hours decrease by at least 15% while factual-correction frequency remains below 5% and every cited variance reconciles to the approved ledger extract. | AK9: The comparison uses the immediately preceding operating window without a concurrent control; attribution is therefore capped and alternative explanations must be listed. | AL9: CONSTRUCTED-EVIDENCE/OV-P08/v1.1 | AM9: The constructed evidence package identifies the measurement extract, evaluator rubric, reconciliation check, and content hash needed for replay. | AN9: Accepted-commentary records are available, but correction reasons were not coded consistently in the first week. | AO9: Value uses recorded analyst minutes and verified avoided processing cost; regulatory and fairness outcomes remain separate constraints. | AP9: Provider, infrastructure, and tooling cost are assigned from workflow trace identifiers; human review and rework use recorded minutes at loaded rates; integration and governance are amortized over the measurement window using the registered allocation key. | AQ9: Expected harm combines prespecified compliance/fairness event probabilities with approved remediation-cost ranges; legal prohibitions remain hard constraints. | AR9: At day 30, the accountable portfolio committee chooses STOP, REVISE, CONTINUE_PILOT, SCALE, or INDETERMINATE and records a signed decision receipt.
A10: OV-P09 | B10: PF-A | C10: ECOMMERCE | D10: CONSTRUCTED | E10: PILOT | F10: Catalog product-description generation | G10: A grounded generator drafts descriptions from verified product attributes for editor approval. | H10: 45 | I10: 15000 | J10: 0.81 | K10: 42 | L10: 14.8 | M10: 3900 | N10: 600 | O10: 550 | P10: 1700 | Q10: 1900 | R10: 450 | S10: 600 | T10: 0.92 | U10: 34000 | V10: TRUE | W10: Increase accepted catalog entries per editor hour without increasing attribute-error returns. Acceptance criteria: Accepted catalog entries per editor hour increase by at least 25%, attribute-error rate remains below 1%, and attribute-related return rate does not increase by more than 0.5 points. | X10: 41000 | Y10: 15000 | Z10: VERIFIED | AA10: RANDOMIZED | AB10: 0.88 | AC10: 3200 | AD10: 250 | AE10: PASS | AF10: 800 | AG10: STANDARD | AH10: FALSE | AI10: 1.1 | AJ10: Accepted catalog entries per editor hour increase by at least 25%, attribute-error rate remains below 1%, and attribute-related return rate does not increase by more than 0.5 points. | AK10: Eligible episodes are assigned 1:1 within site and complexity strata; analysis follows assigned group and records crossover. | AL10: CONSTRUCTED-EVIDENCE/OV-P09/v1.1 | AM10: The constructed evidence package identifies the measurement extract, evaluator rubric, reconciliation check, and content hash needed for replay. | AN10: No material evidence gap is registered for the constructed case. | AO10: Value uses experimentally or concurrently estimated contribution margin and recorded operating cost, net of discounts, returns, and review effort. | AP10: Provider, infrastructure, and tooling cost are assigned from workflow trace identifiers; human review and rework use recorded minutes at loaded rates; integration and governance are amortized over the measurement window using the registered allocation key. | AQ10: Expected harm covers consent, policy, customer-remediation, and fairness events using registered probability and cost ranges. | AR10: At day 45, the accountable portfolio committee chooses STOP, REVISE, CONTINUE_PILOT, SCALE, or INDETERMINATE and records a signed decision receipt.
A11: OV-P10 | B11: PF-B | C11: ECOMMERCE | D11: CONSTRUCTED | E11: PILOT | F11: Returns-resolution chat agent | G11: An agent proposes return eligibility and resolution steps for service representatives. | H11: 60 | I11: 17000 | J11: 0.9 | K11: 75 | L11: 20.5 | M11: 5400 | N11: 900 | O11: 650 | P11: 3200 | Q11: 2300 | R11: 650 | S11: 4100 | T11: 0.87 | U11: 39000 | V11: TRUE | W11: Reduce handling time while maintaining correct return-policy application and repeat-contact rate. Acceptance criteria: Median handling time decreases by at least 15%, incorrect eligibility decisions remain below 2%, and repeat-contact rate does not increase by more than 2 points. | X11: 46000 | Y11: 17000 | Z11: VERIFIED | AA11: STEPPED_WEDGE | AB11: 0.76 | AC11: 5000 | AD11: 1100 | AE11: PASS | AF11: 1300 | AG11: STANDARD | AH11: FALSE | AI11: 1.1 | AJ11: Median handling time decreases by at least 15%, incorrect eligibility decisions remain below 2%, and repeat-contact rate does not increase by more than 2 points. | AK11: Operational units cross over on a prespecified schedule; the model includes unit and calendar-period effects and records concurrent interventions. | AL11: CONSTRUCTED-EVIDENCE/OV-P10/v1.1 | AM11: The constructed evidence package identifies the measurement extract, evaluator rubric, reconciliation check, and content hash needed for replay. | AN11: No material evidence gap is registered for the constructed case. | AO11: Value uses experimentally or concurrently estimated contribution margin and recorded operating cost, net of discounts, returns, and review effort. | AP11: Provider, infrastructure, and tooling cost are assigned from workflow trace identifiers; human review and rework use recorded minutes at loaded rates; integration and governance are amortized over the measurement window using the registered allocation key. | AQ11: Expected harm covers consent, policy, customer-remediation, and fairness events using registered probability and cost ranges. | AR11: At day 60, the accountable portfolio committee chooses STOP, REVISE, CONTINUE_PILOT, SCALE, or INDETERMINATE and records a signed decision receipt.
A12: OV-P11 | B12: PF-C | C12: ECOMMERCE | D12: CONSTRUCTED | E12: PRE_PRODUCTION | F12: Personalized offer recommendation | G12: A recommendation service selects promotional offers using browsing and purchase signals. | H12: 90 | I12: 26000 | J12: 0.77 | K12: 120 | L12: 24 | M12: 6500 | N12: 1500 | O12: 1000 | P12: 2500 | Q12: 3900 | R12: 1100 | S12: 700 | T12: 0.9 | U12: 61000 | V12: TRUE | W12: Increase incremental contribution margin per eligible visitor subject to consent and offer-fairness constraints. Acceptance criteria: Incremental contribution margin per eligible visitor is positive with a lower bound above zero, consent eligibility is 100%, and offer-rate disparity remains within the approved 3-point limit. | X12: 69000 | Y12: 26000 | Z12: PARTIAL | AA12: MATCHED_CONCURRENT | AB12: 0.66 | AC12: 8000 | AD12: 7600 | AE12: PROHIBITED | AF12: 1900 | AG12: MINIMUM_ACCESS | AH12: FALSE | AI12: 1.1 | AJ12: Incremental contribution margin per eligible visitor is positive with a lower bound above zero, consent eligibility is 100%, and offer-rate disparity remains within the approved 3-point limit. | AK12: AI-assisted episodes are matched to concurrent non-AI episodes on workflow type, complexity band, site, and operator-experience band before outcomes are inspected. | AL12: CONSTRUCTED-EVIDENCE/OV-P11/v1.1 | AM12: The constructed evidence package identifies the measurement extract, evaluator rubric, reconciliation check, and content hash needed for replay. | AN12: Contribution-margin evidence is available, but cross-device consent linkage remains incomplete for part of the cohort. | AO12: Value uses experimentally or concurrently estimated contribution margin and recorded operating cost, net of discounts, returns, and review effort. | AP12: Provider, infrastructure, and tooling cost are assigned from workflow trace identifiers; human review and rework use recorded minutes at loaded rates; integration and governance are amortized over the measurement window using the registered allocation key. | AQ12: Expected harm covers consent, policy, customer-remediation, and fairness events using registered probability and cost ranges. | AR12: At day 90, the accountable portfolio committee chooses STOP, REVISE, CONTINUE_PILOT, SCALE, or INDETERMINATE and records a signed decision receipt.
A13: OV-P12 | B13: PF-D | C13: ECOMMERCE | D13: CONSTRUCTED | E13: POC | F13: Natural-language storefront search | G13: A retrieval system rewrites queries and reranks products for low-result searches. | H13: 30 | I13: 11000 | J13: 0.52 | K13: 18 | L13: 7 | M13: 2400 | N13: 500 | O13: 350 | P13: 1100 | Q13: 1600 | R13: 350 | S13: 250 | T13: 0.81 | U13: 17500 | V13: TRUE | W13: Increase successful product discovery for low-result queries without increasing irrelevant clicks. Acceptance criteria: Successful discovery among low-result queries increases by at least 10%, irrelevant-click rate does not increase by more than 2 points, and zero-result rate falls by at least 5%. | X13: 24500 | Y13: 10500 | Z13: VERIFIED | AA13: MATCHED_CONCURRENT | AB13: 0.74 | AC13: 3800 | AD13: 200 | AE13: PASS | AF13: 900 | AG13: EXPLORATION | AH13: TRUE | AI13: 1.1 | AJ13: Successful discovery among low-result queries increases by at least 10%, irrelevant-click rate does not increase by more than 2 points, and zero-result rate falls by at least 5%. | AK13: AI-assisted episodes are matched to concurrent non-AI episodes on workflow type, complexity band, site, and operator-experience band before outcomes are inspected. | AL13: CONSTRUCTED-EVIDENCE/OV-P12/v1.1 | AM13: The constructed evidence package identifies the measurement extract, evaluator rubric, reconciliation check, and content hash needed for replay. | AN13: No material evidence gap is registered for the constructed case. | AO13: Value uses experimentally or concurrently estimated contribution margin and recorded operating cost, net of discounts, returns, and review effort. | AP13: Provider, infrastructure, and tooling cost are assigned from workflow trace identifiers; human review and rework use recorded minutes at loaded rates; integration and governance are amortized over the measurement window using the registered allocation key. | AQ13: Expected harm covers consent, policy, customer-remediation, and fairness events using registered probability and cost ranges. | AR13: At day 30, the accountable portfolio committee chooses STOP, REVISE, CONTINUE_PILOT, SCALE, or INDETERMINATE and records a signed decision receipt.
A14: OV-P13 | B14: PF-A | C14: TRANSPORT_LOGISTICS | D14: CONSTRUCTED | E14: PILOT | F14: Last-mile dispatch optimization | G14: An AI planner proposes route and stop assignments that dispatchers approve before release. | H14: 60 | I14: 24000 | J14: 0.73 | K14: 55 | L14: 15.5 | M14: 4600 | N14: 1100 | O14: 650 | P14: 2300 | Q14: 3400 | R14: 800 | S14: 500 | T14: 0.88 | U14: 47000 | V14: TRUE | W14: Reduce fuel and late-delivery cost per route while preserving driver-hour and service constraints. Acceptance criteria: Fuel plus late-delivery cost per completed route decreases by at least 8%, on-time delivery does not worsen, and driver-hour limits have zero violations. | X14: 57000 | Y14: 21000 | Z14: VERIFIED | AA14: STEPPED_WEDGE | AB14: 0.84 | AC14: 4500 | AD14: 700 | AE14: PASS | AF14: 1200 | AG14: STANDARD | AH14: FALSE | AI14: 1.1 | AJ14: Fuel plus late-delivery cost per completed route decreases by at least 8%, on-time delivery does not worsen, and driver-hour limits have zero violations. | AK14: Operational units cross over on a prespecified schedule; the model includes unit and calendar-period effects and records concurrent interventions. | AL14: CONSTRUCTED-EVIDENCE/OV-P13/v1.1 | AM14: The constructed evidence package identifies the measurement extract, evaluator rubric, reconciliation check, and content hash needed for replay. | AN14: No material evidence gap is registered for the constructed case. | AO14: Value uses reconciled fuel, labor, delay, inventory, or document-processing cost; service and safety outcomes remain separate constraints. | AP14: Provider, infrastructure, and tooling cost are assigned from workflow trace identifiers; human review and rework use recorded minutes at loaded rates; integration and governance are amortized over the measurement window using the registered allocation key. | AQ14: Expected harm covers service, safety, labor-rule, inventory, and customs exceptions using registered operational severity bands. | AR14: At day 60, the accountable portfolio committee chooses STOP, REVISE, CONTINUE_PILOT, SCALE, or INDETERMINATE and records a signed decision receipt.
A15: OV-P14 | B15: PF-B | C15: TRANSPORT_LOGISTICS | D15: CONSTRUCTED | E15: PILOT | F15: Shipment ETA explanation | G15: A model generates customer ETA explanations from carrier events and route status. | H15: 45 | I15: 13000 | J15: 0.64 | K15: 28 | L15: 9.5 | M15: 3000 | N15: 650 | O15: 400 | P15: 1600 | Q15: 1500 | R15: 400 | S15: 550 | T15: 0.82 | U15: 21000 | V15: TRUE | W15: Reduce manual ETA enquiries without increasing inaccurate promise-window statements. Acceptance criteria: Manual ETA enquiries decrease by at least 15%, inaccurate promise-window statements remain below 2%, and repeat ETA contacts do not increase by more than 2 points. | X15: 29000 | Y15: 14000 | Z15: PARTIAL | AA15: INTERRUPTED_TIME_SERIES | AB15: 0.63 | AC15: 5200 | AD15: 800 | AE15: PASS | AF15: 1000 | AG15: STANDARD | AH15: FALSE | AI15: 1.1 | AJ15: Manual ETA enquiries decrease by at least 15%, inaccurate promise-window statements remain below 2%, and repeat ETA contacts do not increase by more than 2 points. | AK15: Weekly outcome series includes at least eight pre-period and eight post-period observations with level, slope, seasonality, and concurrent-shock annotations. | AL15: CONSTRUCTED-EVIDENCE/OV-P14/v1.1 | AM15: The constructed evidence package identifies the measurement extract, evaluator rubric, reconciliation check, and content hash needed for replay. | AN15: Contact and promise-window logs are complete; carrier-caused exception attribution is incomplete. | AO15: Value uses reconciled fuel, labor, delay, inventory, or document-processing cost; service and safety outcomes remain separate constraints. | AP15: Provider, infrastructure, and tooling cost are assigned from workflow trace identifiers; human review and rework use recorded minutes at loaded rates; integration and governance are amortized over the measurement window using the registered allocation key. | AQ15: Expected harm covers service, safety, labor-rule, inventory, and customs exceptions using registered operational severity bands. | AR15: At day 45, the accountable portfolio committee chooses STOP, REVISE, CONTINUE_PILOT, SCALE, or INDETERMINATE and records a signed decision receipt.
A16: OV-P15 | B16: PF-C | C16: TRANSPORT_LOGISTICS | D16: CONSTRUCTED | E16: POC | F16: Warehouse replenishment suggestion | G16: An assistant recommends replenishment quantities from demand and stock telemetry. | H16: 30 | I16: 12000 | J16: 0.71 | K16: 22 | L16: 8.4 | M16: 2700 | N16: 700 | O16: 450 | P16: 1500 | Q16: 1800 | R16: 500 | S16: 350 | T16: 0.8 | U16: 26000 | V16: FALSE | W16: Outcome contract not yet registered. Acceptance criteria: Stockout cost falls by at least 8%, excess-inventory cost does not increase by more than 3%, and no replenishment breaches storage or safety constraints. | X16: 32000 | Z16: UNVERIFIED | AA16: NONE | AB16: 0.4 | AC16: 7000 | AD16: 1200 | AE16: CONDITIONAL | AF16: 1400 | AG16: EXPLORATION | AH16: TRUE | AI16: 1.1 | AJ16: Stockout cost falls by at least 8%, excess-inventory cost does not increase by more than 3%, and no replenishment breaches storage or safety constraints. | AK16: No defensible incremental comparator has been registered; the case cannot support a positive causal ROI classification. | AL16: CONSTRUCTED-EVIDENCE/OV-P15/v1.1 | AM16: No eligible evidence package exists; the locator records the missing-evidence receipt only. | AN16: Outcome evidence and comparator evidence have not passed independent review. | AO16: Value uses reconciled fuel, labor, delay, inventory, or document-processing cost; service and safety outcomes remain separate constraints. | AP16: Provider, infrastructure, and tooling cost are assigned from workflow trace identifiers; human review and rework use recorded minutes at loaded rates; integration and governance are amortized over the measurement window using the registered allocation key. | AQ16: Expected harm covers service, safety, labor-rule, inventory, and customs exceptions using registered operational severity bands. | AR16: At day 30, the accountable portfolio committee chooses STOP, REVISE, CONTINUE_PILOT, SCALE, or INDETERMINATE and records a signed decision receipt.
A17: OV-P16 | B17: PF-D | C17: TRANSPORT_LOGISTICS | D17: CONSTRUCTED | E17: PILOT | F17: Freight-document extraction | G17: A multimodal model extracts shipment fields for operations staff to confirm. | H17: 60 | I17: 15500 | J17: 0.83 | K17: 39 | L17: 17.2 | M17: 4700 | N17: 900 | O17: 600 | P17: 3100 | Q17: 2100 | R17: 550 | S17: 300 | T17: 0.84 | U17: 30000 | V17: TRUE | W17: Reduce manual data-entry cost while holding corrected extraction errors below the registered limit. Acceptance criteria: Manual entry minutes per shipment decrease by at least 20%, corrected extraction fields remain below 2%, and no mandatory customs field is omitted. | X17: 33000 | Y17: 14500 | Z17: VERIFIED | AA17: MATCHED_CONCURRENT | AB17: 0.77 | AC17: 4500 | AD17: 300 | AE17: PASS | AF17: 850 | AG17: STANDARD | AH17: FALSE | AI17: 1.1 | AJ17: Manual entry minutes per shipment decrease by at least 20%, corrected extraction fields remain below 2%, and no mandatory customs field is omitted. | AK17: AI-assisted episodes are matched to concurrent non-AI episodes on workflow type, complexity band, site, and operator-experience band before outcomes are inspected. | AL17: CONSTRUCTED-EVIDENCE/OV-P16/v1.1 | AM17: The constructed evidence package identifies the measurement extract, evaluator rubric, reconciliation check, and content hash needed for replay. | AN17: No material evidence gap is registered for the constructed case. | AO17: Value uses reconciled fuel, labor, delay, inventory, or document-processing cost; service and safety outcomes remain separate constraints. | AP17: Provider, infrastructure, and tooling cost are assigned from workflow trace identifiers; human review and rework use recorded minutes at loaded rates; integration and governance are amortized over the measurement window using the registered allocation key. | AQ17: Expected harm covers service, safety, labor-rule, inventory, and customs exceptions using registered operational severity bands. | AR17: At day 60, the accountable portfolio committee chooses STOP, REVISE, CONTINUE_PILOT, SCALE, or INDETERMINATE and records a signed decision receipt.
A18: OV-P17 | B18: PF-A | C18: CYBERSECURITY | D18: CONSTRUCTED | E18: PILOT | F18: Security-alert triage | G18: An analyst copilot clusters alerts, retrieves runbooks, and drafts triage summaries. | H18: 60 | I18: 21000 | J18: 0.78 | K18: 49 | L18: 18 | M18: 5200 | N18: 1000 | O18: 750 | P18: 2600 | Q18: 2800 | R18: 900 | S18: 650 | T18: 0.91 | U18: 46000 | V18: TRUE | W18: Reduce analyst minutes per correctly resolved alert without increasing missed high-severity incidents. Acceptance criteria: Median analyst minutes per correctly resolved alert decrease by at least 20%, missed high-severity incidents remain at zero, and false escalation does not increase by more than 2 points. | X18: 56000 | Y18: 20000 | Z18: VERIFIED | AA18: RANDOMIZED | AB18: 0.87 | AC18: 4800 | AD18: 1000 | AE18: PASS | AF18: 1500 | AG18: STANDARD | AH18: FALSE | AI18: 1.1 | AJ18: Median analyst minutes per correctly resolved alert decrease by at least 20%, missed high-severity incidents remain at zero, and false escalation does not increase by more than 2 points. | AK18: Eligible episodes are assigned 1:1 within site and complexity strata; analysis follows assigned group and records crossover. | AL18: CONSTRUCTED-EVIDENCE/OV-P17/v1.1 | AM18: The constructed evidence package identifies the measurement extract, evaluator rubric, reconciliation check, and content hash needed for replay. | AN18: No material evidence gap is registered for the constructed case. | AO18: Value uses recorded analyst time and approved incident-loss proxies; security severity is reported separately and is not monetized without an approved model. | AP18: Provider, infrastructure, and tooling cost are assigned from workflow trace identifiers; human review and rework use recorded minutes at loaded rates; integration and governance are amortized over the measurement window using the registered allocation key. | AQ18: Expected harm uses registered incident-severity bands and bounded exposure probabilities; unauthorized execution is a hard constraint. | AR18: At day 60, the accountable portfolio committee chooses STOP, REVISE, CONTINUE_PILOT, SCALE, or INDETERMINATE and records a signed decision receipt.
A19: OV-P18 | B19: PF-B | C19: CYBERSECURITY | D19: CONSTRUCTED | E19: PILOT | F19: Incident-response command suggestion | G19: An agent proposes containment commands that require analyst approval before execution. | H19: 45 | I19: 20000 | J19: 0.62 | K19: 25 | L19: 12 | M19: 4100 | N19: 850 | O19: 650 | P19: 2800 | Q19: 2500 | R19: 1200 | S19: 800 | T19: 0.8 | U19: 37000 | V19: TRUE | W19: Reduce time to approved containment while avoiding unsafe or unauthorized command proposals. Acceptance criteria: Median time to approved containment decreases by at least 15%, no unauthorized command reaches execution, and unsafe-command proposal rate remains below 1%. | X19: 43000 | Y19: 18000 | Z19: PARTIAL | AA19: MATCHED_CONCURRENT | AB19: 0.6 | AC19: 8500 | AD19: 5200 | AE19: CONDITIONAL | AF19: 2100 | AG19: STANDARD | AH19: FALSE | AI19: 1.1 | AJ19: Median time to approved containment decreases by at least 15%, no unauthorized command reaches execution, and unsafe-command proposal rate remains below 1%. | AK19: AI-assisted episodes are matched to concurrent non-AI episodes on workflow type, complexity band, site, and operator-experience band before outcomes are inspected. | AL19: CONSTRUCTED-EVIDENCE/OV-P18/v1.1 | AM19: The constructed evidence package identifies the measurement extract, evaluator rubric, reconciliation check, and content hash needed for replay. | AN19: Approval and execution logs are complete, but rejected unsafe-command proposals lack a uniform severity code. | AO19: Value uses recorded analyst time and approved incident-loss proxies; security severity is reported separately and is not monetized without an approved model. | AP19: Provider, infrastructure, and tooling cost are assigned from workflow trace identifiers; human review and rework use recorded minutes at loaded rates; integration and governance are amortized over the measurement window using the registered allocation key. | AQ19: Expected harm uses registered incident-severity bands and bounded exposure probabilities; unauthorized execution is a hard constraint. | AR19: At day 45, the accountable portfolio committee chooses STOP, REVISE, CONTINUE_PILOT, SCALE, or INDETERMINATE and records a signed decision receipt.
A20: OV-P19 | B20: PF-C | C20: CYBERSECURITY | D20: CONSTRUCTED | E20: POC | F20: Vulnerability remediation prioritization | G20: A model ranks vulnerabilities using asset and threat context for security-engineering review. | H20: 30 | I20: 10000 | J20: 0.7 | K20: 16 | L20: 6.1 | M20: 1900 | N20: 500 | O20: 300 | P20: 1000 | Q20: 1300 | R20: 400 | S20: 250 | T20: 0.85 | U20: 22000 | V20: FALSE | W20: Outcome contract not yet registered. Acceptance criteria: Median time to an accepted remediation queue decreases by at least 15%, critical-asset recall remains at least 98%, and no protected exploration asset is excluded solely for missing history. | X20: 28000 | Z20: UNVERIFIED | AA20: NONE | AB20: 0.35 | AC20: 7500 | AD20: 700 | AE20: CONDITIONAL | AF20: 1700 | AG20: EXPLORATION | AH20: TRUE | AI20: 1.1 | AJ20: Median time to an accepted remediation queue decreases by at least 15%, critical-asset recall remains at least 98%, and no protected exploration asset is excluded solely for missing history. | AK20: No defensible incremental comparator has been registered; the case cannot support a positive causal ROI classification. | AL20: CONSTRUCTED-EVIDENCE/OV-P19/v1.1 | AM20: No eligible evidence package exists; the locator records the missing-evidence receipt only. | AN20: Outcome evidence and comparator evidence have not passed independent review. | AO20: Value uses recorded analyst time and approved incident-loss proxies; security severity is reported separately and is not monetized without an approved model. | AP20: Provider, infrastructure, and tooling cost are assigned from workflow trace identifiers; human review and rework use recorded minutes at loaded rates; integration and governance are amortized over the measurement window using the registered allocation key. | AQ20: Expected harm uses registered incident-severity bands and bounded exposure probabilities; unauthorized execution is a hard constraint. | AR20: At day 30, the accountable portfolio committee chooses STOP, REVISE, CONTINUE_PILOT, SCALE, or INDETERMINATE and records a signed decision receipt.
A21: OV-P20 | B21: PF-D | C21: CYBERSECURITY | D21: CONSTRUCTED | E21: PILOT | F21: Phishing-report classification | G21: A classifier prioritizes employee-reported messages for analyst investigation. | H21: 60 | I21: 14500 | J21: 0.86 | K21: 81 | L21: 16.8 | M21: 4400 | N21: 700 | O21: 500 | P21: 2300 | Q21: 1700 | R21: 500 | S21: 2900 | T21: 0.89 | U21: 33000 | V21: TRUE | W21: Reduce triage time while preserving detection of credential-theft messages and controlling analyst rework. Acceptance criteria: Median triage time decreases by at least 20%, credential-theft recall remains at least 99%, and analyst rework does not exceed the registered 5% ceiling. | X21: 38000 | Y21: 15000 | Z21: VERIFIED | AA21: INTERRUPTED_TIME_SERIES | AB21: 0.73 | AC21: 5000 | AD21: 900 | AE21: PASS | AF21: 1000 | AG21: STANDARD | AH21: FALSE | AI21: 1.1 | AJ21: Median triage time decreases by at least 20%, credential-theft recall remains at least 99%, and analyst rework does not exceed the registered 5% ceiling. | AK21: Weekly outcome series includes at least eight pre-period and eight post-period observations with level, slope, seasonality, and concurrent-shock annotations. | AL21: CONSTRUCTED-EVIDENCE/OV-P20/v1.1 | AM21: The constructed evidence package identifies the measurement extract, evaluator rubric, reconciliation check, and content hash needed for replay. | AN21: No material evidence gap is registered for the constructed case. | AO21: Value uses recorded analyst time and approved incident-loss proxies; security severity is reported separately and is not monetized without an approved model. | AP21: Provider, infrastructure, and tooling cost are assigned from workflow trace identifiers; human review and rework use recorded minutes at loaded rates; integration and governance are amortized over the measurement window using the registered allocation key. | AQ21: Expected harm uses registered incident-severity bands and bounded exposure probabilities; unauthorized execution is a hard constraint. | AR21: At day 60, the accountable portfolio committee chooses STOP, REVISE, CONTINUE_PILOT, SCALE, or INDETERMINATE and records a signed decision receipt.
A22: OV-P21 | B22: PF-A | C22: CUSTOMER_OPERATIONS | D22: CONSTRUCTED | E22: PILOT | F22: Service-case response assistance | G22: A grounded assistant drafts responses from policy and account records for representative approval. | H22: 60 | I22: 19000 | J22: 0.8 | K22: 92 | L22: 22 | M22: 5800 | N22: 850 | O22: 650 | P22: 2500 | Q22: 2300 | R22: 650 | S22: 700 | T22: 0.93 | U22: 48000 | V22: TRUE | W22: Reduce handling time per accepted response without increasing repeat contact or policy error. Acceptance criteria: Median handling time per accepted response decreases by at least 20%, policy-error rate remains below 1%, and repeat-contact rate does not increase by more than 2 points. | X22: 59000 | Y22: 22000 | Z22: VERIFIED | AA22: STEPPED_WEDGE | AB22: 0.85 | AC22: 4200 | AD22: 400 | AE22: PASS | AF22: 1200 | AG22: STANDARD | AH22: FALSE | AI22: 1.1 | AJ22: Median handling time per accepted response decreases by at least 20%, policy-error rate remains below 1%, and repeat-contact rate does not increase by more than 2 points. | AK22: Operational units cross over on a prespecified schedule; the model includes unit and calendar-period effects and records concurrent interventions. | AL22: CONSTRUCTED-EVIDENCE/OV-P21/v1.1 | AM22: The constructed evidence package identifies the measurement extract, evaluator rubric, reconciliation check, and content hash needed for replay. | AN22: No material evidence gap is registered for the constructed case. | AO22: Value uses recorded handling or interpreter time and verified retained margin where applicable, net of review, offer, correction, and repeat-contact cost. | AP22: Provider, infrastructure, and tooling cost are assigned from workflow trace identifiers; human review and rework use recorded minutes at loaded rates; integration and governance are amortized over the measurement window using the registered allocation key. | AQ22: Expected harm covers policy error, inappropriate contact, escalation, and customer-remediation events using registered severity bands. | AR22: At day 60, the accountable portfolio committee chooses STOP, REVISE, CONTINUE_PILOT, SCALE, or INDETERMINATE and records a signed decision receipt.
A23: OV-P22 | B23: PF-B | C23: CUSTOMER_OPERATIONS | D23: CONSTRUCTED | E23: POC | F23: Account-manager email drafting | G23: An assistant prepares follow-up drafts from CRM notes for account-manager editing. | H23: 30 | I23: 9000 | J23: 0.38 | K23: 12 | L23: 4.2 | M23: 1500 | N23: 350 | O23: 250 | P23: 950 | Q23: 1200 | R23: 250 | S23: 150 | T23: 0.76 | U23: 12000 | V23: TRUE | W23: Reduce drafting time for accepted follow-up emails without increasing correction or opt-out rates. Acceptance criteria: Median drafting time decreases by at least 15%, manager acceptance reaches at least 75%, and correction and opt-out rates do not rise by more than 2 and 0.5 points respectively. | X23: 16500 | Y23: 8500 | Z23: VERIFIED | AA23: MATCHED_CONCURRENT | AB23: 0.71 | AC23: 2600 | AD23: 100 | AE23: PASS | AF23: 700 | AG23: EXPLORATION | AH23: TRUE | AI23: 1.1 | AJ23: Median drafting time decreases by at least 15%, manager acceptance reaches at least 75%, and correction and opt-out rates do not rise by more than 2 and 0.5 points respectively. | AK23: AI-assisted episodes are matched to concurrent non-AI episodes on workflow type, complexity band, site, and operator-experience band before outcomes are inspected. | AL23: CONSTRUCTED-EVIDENCE/OV-P22/v1.1 | AM23: The constructed evidence package identifies the measurement extract, evaluator rubric, reconciliation check, and content hash needed for replay. | AN23: No material evidence gap is registered for the constructed case. | AO23: Value uses recorded handling or interpreter time and verified retained margin where applicable, net of review, offer, correction, and repeat-contact cost. | AP23: Provider, infrastructure, and tooling cost are assigned from workflow trace identifiers; human review and rework use recorded minutes at loaded rates; integration and governance are amortized over the measurement window using the registered allocation key. | AQ23: Expected harm covers policy error, inappropriate contact, escalation, and customer-remediation events using registered severity bands. | AR23: At day 30, the accountable portfolio committee chooses STOP, REVISE, CONTINUE_PILOT, SCALE, or INDETERMINATE and records a signed decision receipt.
A24: OV-P23 | B24: PF-C | C24: CUSTOMER_OPERATIONS | D24: CONSTRUCTED | E24: PRE_PRODUCTION | F24: Churn-retention outreach | G24: An agent identifies accounts and drafts retention offers for representative review. | H24: 90 | I24: 25000 | J24: 0.85 | K24: 105 | L24: 27 | M24: 7200 | N24: 1200 | O24: 850 | P24: 4300 | Q24: 3600 | R24: 900 | S24: 5200 | T24: 0.88 | U24: 65000 | V24: TRUE | W24: Increase incremental retained margin net of offer cost without increasing inappropriate-contact complaints. Acceptance criteria: Incremental retained margin net of offer cost has a lower bound above zero, inappropriate-contact complaints do not increase, and all contacted accounts satisfy eligibility rules. | X24: 71000 | Y24: 24000 | Z24: PARTIAL | AA24: BEFORE_AFTER_UNCONTROLLED | AB24: 0.56 | AC24: 9500 | AD24: 2600 | AE24: PASS | AF24: 2200 | AG24: MINIMUM_ACCESS | AH24: FALSE | AI24: 1.1 | AJ24: Incremental retained margin net of offer cost has a lower bound above zero, inappropriate-contact complaints do not increase, and all contacted accounts satisfy eligibility rules. | AK24: The comparison uses the immediately preceding operating window without a concurrent control; attribution is therefore capped and alternative explanations must be listed. | AL24: CONSTRUCTED-EVIDENCE/OV-P23/v1.1 | AM24: The constructed evidence package identifies the measurement extract, evaluator rubric, reconciliation check, and content hash needed for replay. | AN24: Retention and offer-cost records are complete, but some delayed cancellations remain outside the current measurement window. | AO24: Value uses recorded handling or interpreter time and verified retained margin where applicable, net of review, offer, correction, and repeat-contact cost. | AP24: Provider, infrastructure, and tooling cost are assigned from workflow trace identifiers; human review and rework use recorded minutes at loaded rates; integration and governance are amortized over the measurement window using the registered allocation key. | AQ24: Expected harm covers policy error, inappropriate contact, escalation, and customer-remediation events using registered severity bands. | AR24: At day 90, the accountable portfolio committee chooses STOP, REVISE, CONTINUE_PILOT, SCALE, or INDETERMINATE and records a signed decision receipt.
A25: OV-P24 | B25: PF-D | C25: CUSTOMER_OPERATIONS | D25: CONSTRUCTED | E25: PILOT | F25: Multilingual support translation | G25: A language model translates service conversations, with sampled bilingual quality review. | H25: 45 | I25: 12500 | J25: 0.67 | K25: 37 | L25: 10.4 | M25: 3200 | N25: 550 | O25: 450 | P25: 1900 | Q25: 1500 | R25: 400 | S25: 450 | T25: 0.84 | U25: 25000 | V25: TRUE | W25: Reduce interpreter and handling cost while meeting registered translation-accuracy and escalation thresholds. Acceptance criteria: Interpreter plus handling cost decreases by at least 15%, sampled translation accuracy is at least 95%, and missed mandatory escalation cues remain at zero. | X25: 31000 | Y25: 14000 | Z25: PARTIAL | AA25: INTERRUPTED_TIME_SERIES | AB25: 0.64 | AC25: 6100 | AD25: 700 | AE25: PASS | AF25: 1100 | AG25: STANDARD | AH25: FALSE | AI25: 1.1 | AJ25: Interpreter plus handling cost decreases by at least 15%, sampled translation accuracy is at least 95%, and missed mandatory escalation cues remain at zero. | AK25: Weekly outcome series includes at least eight pre-period and eight post-period observations with level, slope, seasonality, and concurrent-shock annotations. | AL25: CONSTRUCTED-EVIDENCE/OV-P24/v1.1 | AM25: The constructed evidence package identifies the measurement extract, evaluator rubric, reconciliation check, and content hash needed for replay. | AN25: Operational samples are complete for four languages; two low-volume languages have fewer than the registered review count. | AO25: Value uses recorded handling or interpreter time and verified retained margin where applicable, net of review, offer, correction, and repeat-contact cost. | AP25: Provider, infrastructure, and tooling cost are assigned from workflow trace identifiers; human review and rework use recorded minutes at loaded rates; integration and governance are amortized over the measurement window using the registered allocation key. | AQ25: Expected harm covers policy error, inappropriate contact, escalation, and customer-remediation events using registered severity bands. | AR25: At day 45, the accountable portfolio committee chooses STOP, REVISE, CONTINUE_PILOT, SCALE, or INDETERMINATE and records a signed decision receipt.

Sheet Scores
A1: case_id | B1: outcome_contract_clarity | C1: baseline_credibility | D1: evidence_auditability | E1: cost_boundary_completeness | F1: attribution_defensibility | G1: decision_realism | H1: leakage_flag | I1: ambiguity_flag | J1: missing_information | K1: boundary_rationale | L1: completed_scores | M1: score_check | N1: boundary_check
A2: OV-P01 | H2: NO | I2: NO | L2: =COUNT(B2:G2) -> 0 | M2: {=IF(AND(L2=6,MIN(B2:G2)>=1,MAX(B2:G2)<=5,SUMPRODUCT(--(MOD(B2:G2,1)=0))=6),"PASS","INCOMPLETE/INVALID")} -> INCOMPLETE/INVALID | N2: =IF(COUNTIF(B2:G2,1)+COUNTIF(B2:G2,5)=0,"PASS",IF(K2<>"","PASS","RATIONALE REQUIRED")) -> PASS
A3: OV-P02 | H3: NO | I3: NO | L3: =COUNT(B3:G3) -> 0 | M3: {=IF(AND(L3=6,MIN(B3:G3)>=1,MAX(B3:G3)<=5,SUMPRODUCT(--(MOD(B3:G3,1)=0))=6),"PASS","INCOMPLETE/INVALID")} -> INCOMPLETE/INVALID | N3: =IF(COUNTIF(B3:G3,1)+COUNTIF(B3:G3,5)=0,"PASS",IF(K3<>"","PASS","RATIONALE REQUIRED")) -> PASS
A4: OV-P03 | H4: NO | I4: NO | L4: =COUNT(B4:G4) -> 0 | M4: {=IF(AND(L4=6,MIN(B4:G4)>=1,MAX(B4:G4)<=5,SUMPRODUCT(--(MOD(B4:G4,1)=0))=6),"PASS","INCOMPLETE/INVALID")} -> INCOMPLETE/INVALID | N4: =IF(COUNTIF(B4:G4,1)+COUNTIF(B4:G4,5)=0,"PASS",IF(K4<>"","PASS","RATIONALE REQUIRED")) -> PASS
A5: OV-P04 | H5: NO | I5: NO | L5: =COUNT(B5:G5) -> 0 | M5: {=IF(AND(L5=6,MIN(B5:G5)>=1,MAX(B5:G5)<=5,SUMPRODUCT(--(MOD(B5:G5,1)=0))=6),"PASS","INCOMPLETE/INVALID")} -> INCOMPLETE/INVALID | N5: =IF(COUNTIF(B5:G5,1)+COUNTIF(B5:G5,5)=0,"PASS",IF(K5<>"","PASS","RATIONALE REQUIRED")) -> PASS
A6: OV-P05 | H6: NO | I6: NO | L6: =COUNT(B6:G6) -> 0 | M6: {=IF(AND(L6=6,MIN(B6:G6)>=1,MAX(B6:G6)<=5,SUMPRODUCT(--(MOD(B6:G6,1)=0))=6),"PASS","INCOMPLETE/INVALID")} -> INCOMPLETE/INVALID | N6: =IF(COUNTIF(B6:G6,1)+COUNTIF(B6:G6,5)=0,"PASS",IF(K6<>"","PASS","RATIONALE REQUIRED")) -> PASS
A7: OV-P06 | H7: NO | I7: NO | L7: =COUNT(B7:G7) -> 0 | M7: {=IF(AND(L7=6,MIN(B7:G7)>=1,MAX(B7:G7)<=5,SUMPRODUCT(--(MOD(B7:G7,1)=0))=6),"PASS","INCOMPLETE/INVALID")} -> INCOMPLETE/INVALID | N7: =IF(COUNTIF(B7:G7,1)+COUNTIF(B7:G7,5)=0,"PASS",IF(K7<>"","PASS","RATIONALE REQUIRED")) -> PASS
A8: OV-P07 | H8: NO | I8: NO | L8: =COUNT(B8:G8) -> 0 | M8: {=IF(AND(L8=6,MIN(B8:G8)>=1,MAX(B8:G8)<=5,SUMPRODUCT(--(MOD(B8:G8,1)=0))=6),"PASS","INCOMPLETE/INVALID")} -> INCOMPLETE/INVALID | N8: =IF(COUNTIF(B8:G8,1)+COUNTIF(B8:G8,5)=0,"PASS",IF(K8<>"","PASS","RATIONALE REQUIRED")) -> PASS
A9: OV-P08 | H9: NO | I9: NO | L9: =COUNT(B9:G9) -> 0 | M9: {=IF(AND(L9=6,MIN(B9:G9)>=1,MAX(B9:G9)<=5,SUMPRODUCT(--(MOD(B9:G9,1)=0))=6),"PASS","INCOMPLETE/INVALID")} -> INCOMPLETE/INVALID | N9: =IF(COUNTIF(B9:G9,1)+COUNTIF(B9:G9,5)=0,"PASS",IF(K9<>"","PASS","RATIONALE REQUIRED")) -> PASS
A10: OV-P09 | H10: NO | I10: NO | L10: =COUNT(B10:G10) -> 0 | M10: {=IF(AND(L10=6,MIN(B10:G10)>=1,MAX(B10:G10)<=5,SUMPRODUCT(--(MOD(B10:G10,1)=0))=6),"PASS","INCOMPLETE/INVALID")} -> INCOMPLETE/INVALID | N10: =IF(COUNTIF(B10:G10,1)+COUNTIF(B10:G10,5)=0,"PASS",IF(K10<>"","PASS","RATIONALE REQUIRED")) -> PASS
A11: OV-P10 | H11: NO | I11: NO | L11: =COUNT(B11:G11) -> 0 | M11: {=IF(AND(L11=6,MIN(B11:G11)>=1,MAX(B11:G11)<=5,SUMPRODUCT(--(MOD(B11:G11,1)=0))=6),"PASS","INCOMPLETE/INVALID")} -> INCOMPLETE/INVALID | N11: =IF(COUNTIF(B11:G11,1)+COUNTIF(B11:G11,5)=0,"PASS",IF(K11<>"","PASS","RATIONALE REQUIRED")) -> PASS
A12: OV-P11 | H12: NO | I12: NO | L12: =COUNT(B12:G12) -> 0 | M12: {=IF(AND(L12=6,MIN(B12:G12)>=1,MAX(B12:G12)<=5,SUMPRODUCT(--(MOD(B12:G12,1)=0))=6),"PASS","INCOMPLETE/INVALID")} -> INCOMPLETE/INVALID | N12: =IF(COUNTIF(B12:G12,1)+COUNTIF(B12:G12,5)=0,"PASS",IF(K12<>"","PASS","RATIONALE REQUIRED")) -> PASS
A13: OV-P12 | H13: NO | I13: NO | L13: =COUNT(B13:G13) -> 0 | M13: {=IF(AND(L13=6,MIN(B13:G13)>=1,MAX(B13:G13)<=5,SUMPRODUCT(--(MOD(B13:G13,1)=0))=6),"PASS","INCOMPLETE/INVALID")} -> INCOMPLETE/INVALID | N13: =IF(COUNTIF(B13:G13,1)+COUNTIF(B13:G13,5)=0,"PASS",IF(K13<>"","PASS","RATIONALE REQUIRED")) -> PASS
... A25: OV-P24 | H25: NO | I25: NO | L25: =COUNT(B25:G25) -> 0 | M25: {=IF(AND(L25=6,MIN(B25:G25)>=1,MAX(B25:G25)<=5,SUMPRODUCT(--(MOD(B25:G25,1)=0))=6),"PASS","INCOMPLETE/INVALID")} -> INCOMPLETE/INVALID | N25: =IF(COUNTIF(B25:G25,1)+COUNTIF(B25:G25,5)=0,"PASS",IF(K25<>"","PASS","RATIONALE REQUIRED")) -> PASS

Sheet Rubrics
A1: Dimension | B1: Definition | C1: 1 — Not usable | D1: 2 — Weak | E1: 3 — Adequate | F1: 4 — Strong | G1: 5 — Exemplary
A2: Outcome contract clarity | B2: Specificity of outcome, workflow/population, measurement window, and acceptance boundary. | C2: Cannot identify outcome or rule. | D2: Material elements absent. | E2: Scoreable with important ambiguity. | F2: Clear with minor limitation. | G2: Fully specified and decision-ready.
A3: Baseline credibility | B3: Ability of the stated design to support an incremental comparison. | C3: No comparator or unusable design. | D3: Major identification weakness. | E3: Plausible but important assumptions. | F3: Strong design with stated assumptions. | G3: Highly credible and reproducible design.
A4: Evidence auditability | B4: Whether an independent reviewer can inspect and reproduce the outcome assessment. | C4: No eligible evidence package. | D4: Major evidence/reproduction gaps. | E4: Partially auditable. | F4: Auditable with minor limitation. | G4: Complete locator, hash, rubric, and replay trail.
